Watching for file changes with StatReloader
Watching for file changes with StatReloader
[24/Apr/2019 04:21:40] "GET /e/puy4/notes/ HTTP/1.1" 200 1576
[24/Apr/2019 04:21:48] "GET /e/puy4/notes/ HTTP/1.1" 200 1576
[24/Apr/2019 04:21:50] "GET /e/puy4/notes/ HTTP/1.1" 200 1576
[24/Apr/2019 04:21:51] "GET /e/puy4/ HTTP/1.1" 200 1450
[24/Apr/2019 04:21:54] "GET /e/puy4/ HTTP/1.1" 200 1450
[24/Apr/2019 04:23:10] "GET /e/puy4/ HTTP/1.1" 200 1450
[24/Apr/2019 04:23:13] "GET /e/puy4/notes/ HTTP/1.1" 200 1582
[24/Apr/2019 04:23:45] "GET /e/puy4/notes/ HTTP/1.1" 200 1552
[24/Apr/2019 04:25:15] "GET /e/puy4/notes/ HTTP/1.1" 200 1552
Internal Server Error: /e/puy4/
Traceback (most recent call last):
  File "/home/puy4/CS1XA3/Project03/python_env/lib/python3.6/site-packages/django/urls/base.py", line 75, in reverse
    extra, resolver = resolver.namespace_dict[ns]
KeyError: 'user'

During handling of the above exception, another exception occurred:

Traceback (most recent call last):
  File "/home/puy4/CS1XA3/Project03/python_env/lib/python3.6/site-packages/django/core/handlers/exception.py", line 34, in inner
    response = get_response(request)
  File "/home/puy4/CS1XA3/Project03/python_env/lib/python3.6/site-packages/django/core/handlers/base.py", line 115, in _get_response
    response = self.process_exception_by_middleware(e, request)
  File "/home/puy4/CS1XA3/Project03/python_env/lib/python3.6/site-packages/django/core/handlers/base.py", line 113, in _get_response
    response = wrapped_callback(request, *callback_args, **callback_kwargs)
  File "/home/puy4/CS1XA3/Project03/django_project/homepage1/views.py", line 9, in home
    return render(request, 'home.html', hometitle)
  File "/home/puy4/CS1XA3/Project03/python_env/lib/python3.6/site-packages/django/shortcuts.py", line 36, in render
    content = loader.render_to_string(template_name, context, request, using=using)
  File "/home/puy4/CS1XA3/Project03/python_env/lib/python3.6/site-packages/django/template/loader.py", line 62, in render_to_string
    return template.render(context, request)
  File "/home/puy4/CS1XA3/Project03/python_env/lib/python3.6/site-packages/django/template/backends/django.py", line 61, in render
    return self.template.render(context)
  File "/home/puy4/CS1XA3/Project03/python_env/lib/python3.6/site-packages/django/template/base.py", line 171, in render
    return self._render(context)
  File "/home/puy4/CS1XA3/Project03/python_env/lib/python3.6/site-packages/django/template/base.py", line 163, in _render
    return self.nodelist.render(context)
  File "/home/puy4/CS1XA3/Project03/python_env/lib/python3.6/site-packages/django/template/base.py", line 937, in render
    bit = node.render_annotated(context)
  File "/home/puy4/CS1XA3/Project03/python_env/lib/python3.6/site-packages/django/template/base.py", line 904, in render_annotated
    return self.render(context)
  File "/home/puy4/CS1XA3/Project03/python_env/lib/python3.6/site-packages/django/template/loader_tags.py", line 150, in render
    return compiled_parent._render(context)
  File "/home/puy4/CS1XA3/Project03/python_env/lib/python3.6/site-packages/django/template/base.py", line 163, in _render
    return self.nodelist.render(context)
  File "/home/puy4/CS1XA3/Project03/python_env/lib/python3.6/site-packages/django/template/base.py", line 937, in render
    bit = node.render_annotated(context)
  File "/home/puy4/CS1XA3/Project03/python_env/lib/python3.6/site-packages/django/template/base.py", line 904, in render_annotated
    return self.render(context)
  File "/home/puy4/CS1XA3/Project03/python_env/lib/python3.6/site-packages/django/template/loader_tags.py", line 62, in render
    result = block.nodelist.render(context)
  File "/home/puy4/CS1XA3/Project03/python_env/lib/python3.6/site-packages/django/template/base.py", line 937, in render
    bit = node.render_annotated(context)
  File "/home/puy4/CS1XA3/Project03/python_env/lib/python3.6/site-packages/django/template/base.py", line 904, in render_annotated
    return self.render(context)
  File "/home/puy4/CS1XA3/Project03/python_env/lib/python3.6/site-packages/django/template/defaulttags.py", line 443, in render
    url = reverse(view_name, args=args, kwargs=kwargs, current_app=current_app)
  File "/home/puy4/CS1XA3/Project03/python_env/lib/python3.6/site-packages/django/urls/base.py", line 86, in reverse
    raise NoReverseMatch("%s is not a registered namespace" % key)
django.urls.exceptions.NoReverseMatch: 'user' is not a registered namespace
[24/Apr/2019 04:37:02] "GET /e/puy4/ HTTP/1.1" 500 146323
Internal Server Error: /e/puy4/
Traceback (most recent call last):
  File "/home/puy4/CS1XA3/Project03/python_env/lib/python3.6/site-packages/django/urls/base.py", line 75, in reverse
    extra, resolver = resolver.namespace_dict[ns]
KeyError: 'users'

During handling of the above exception, another exception occurred:

Traceback (most recent call last):
  File "/home/puy4/CS1XA3/Project03/python_env/lib/python3.6/site-packages/django/core/handlers/exception.py", line 34, in inner
    response = get_response(request)
  File "/home/puy4/CS1XA3/Project03/python_env/lib/python3.6/site-packages/django/core/handlers/base.py", line 115, in _get_response
    response = self.process_exception_by_middleware(e, request)
  File "/home/puy4/CS1XA3/Project03/python_env/lib/python3.6/site-packages/django/core/handlers/base.py", line 113, in _get_response
    response = wrapped_callback(request, *callback_args, **callback_kwargs)
  File "/home/puy4/CS1XA3/Project03/django_project/homepage1/views.py", line 9, in home
    return render(request, 'home.html', hometitle)
  File "/home/puy4/CS1XA3/Project03/python_env/lib/python3.6/site-packages/django/shortcuts.py", line 36, in render
    content = loader.render_to_string(template_name, context, request, using=using)
  File "/home/puy4/CS1XA3/Project03/python_env/lib/python3.6/site-packages/django/template/loader.py", line 62, in render_to_string
    return template.render(context, request)
  File "/home/puy4/CS1XA3/Project03/python_env/lib/python3.6/site-packages/django/template/backends/django.py", line 61, in render
    return self.template.render(context)
  File "/home/puy4/CS1XA3/Project03/python_env/lib/python3.6/site-packages/django/template/base.py", line 171, in render
    return self._render(context)
  File "/home/puy4/CS1XA3/Project03/python_env/lib/python3.6/site-packages/django/template/base.py", line 163, in _render
    return self.nodelist.render(context)
  File "/home/puy4/CS1XA3/Project03/python_env/lib/python3.6/site-packages/django/template/base.py", line 937, in render
    bit = node.render_annotated(context)
  File "/home/puy4/CS1XA3/Project03/python_env/lib/python3.6/site-packages/django/template/base.py", line 904, in render_annotated
    return self.render(context)
  File "/home/puy4/CS1XA3/Project03/python_env/lib/python3.6/site-packages/django/template/loader_tags.py", line 150, in render
    return compiled_parent._render(context)
  File "/home/puy4/CS1XA3/Project03/python_env/lib/python3.6/site-packages/django/template/base.py", line 163, in _render
    return self.nodelist.render(context)
  File "/home/puy4/CS1XA3/Project03/python_env/lib/python3.6/site-packages/django/template/base.py", line 937, in render
    bit = node.render_annotated(context)
  File "/home/puy4/CS1XA3/Project03/python_env/lib/python3.6/site-packages/django/template/base.py", line 904, in render_annotated
    return self.render(context)
  File "/home/puy4/CS1XA3/Project03/python_env/lib/python3.6/site-packages/django/template/loader_tags.py", line 62, in render
    result = block.nodelist.render(context)
  File "/home/puy4/CS1XA3/Project03/python_env/lib/python3.6/site-packages/django/template/base.py", line 937, in render
    bit = node.render_annotated(context)
  File "/home/puy4/CS1XA3/Project03/python_env/lib/python3.6/site-packages/django/template/base.py", line 904, in render_annotated
    return self.render(context)
  File "/home/puy4/CS1XA3/Project03/python_env/lib/python3.6/site-packages/django/template/defaulttags.py", line 443, in render
    url = reverse(view_name, args=args, kwargs=kwargs, current_app=current_app)
  File "/home/puy4/CS1XA3/Project03/python_env/lib/python3.6/site-packages/django/urls/base.py", line 86, in reverse
    raise NoReverseMatch("%s is not a registered namespace" % key)
django.urls.exceptions.NoReverseMatch: 'users' is not a registered namespace
[24/Apr/2019 04:37:46] "GET /e/puy4/ HTTP/1.1" 500 146338
Internal Server Error: /e/puy4/
Traceback (most recent call last):
  File "/home/puy4/CS1XA3/Project03/python_env/lib/python3.6/site-packages/django/urls/base.py", line 75, in reverse
    extra, resolver = resolver.namespace_dict[ns]
KeyError: 'users'

During handling of the above exception, another exception occurred:

Traceback (most recent call last):
  File "/home/puy4/CS1XA3/Project03/python_env/lib/python3.6/site-packages/django/core/handlers/exception.py", line 34, in inner
    response = get_response(request)
  File "/home/puy4/CS1XA3/Project03/python_env/lib/python3.6/site-packages/django/core/handlers/base.py", line 115, in _get_response
    response = self.process_exception_by_middleware(e, request)
  File "/home/puy4/CS1XA3/Project03/python_env/lib/python3.6/site-packages/django/core/handlers/base.py", line 113, in _get_response
    response = wrapped_callback(request, *callback_args, **callback_kwargs)
  File "/home/puy4/CS1XA3/Project03/django_project/homepage1/views.py", line 9, in home
    return render(request, 'home.html', hometitle)
  File "/home/puy4/CS1XA3/Project03/python_env/lib/python3.6/site-packages/django/shortcuts.py", line 36, in render
    content = loader.render_to_string(template_name, context, request, using=using)
  File "/home/puy4/CS1XA3/Project03/python_env/lib/python3.6/site-packages/django/template/loader.py", line 62, in render_to_string
    return template.render(context, request)
  File "/home/puy4/CS1XA3/Project03/python_env/lib/python3.6/site-packages/django/template/backends/django.py", line 61, in render
    return self.template.render(context)
  File "/home/puy4/CS1XA3/Project03/python_env/lib/python3.6/site-packages/django/template/base.py", line 171, in render
    return self._render(context)
  File "/home/puy4/CS1XA3/Project03/python_env/lib/python3.6/site-packages/django/template/base.py", line 163, in _render
    return self.nodelist.render(context)
  File "/home/puy4/CS1XA3/Project03/python_env/lib/python3.6/site-packages/django/template/base.py", line 937, in render
    bit = node.render_annotated(context)
  File "/home/puy4/CS1XA3/Project03/python_env/lib/python3.6/site-packages/django/template/base.py", line 904, in render_annotated
    return self.render(context)
  File "/home/puy4/CS1XA3/Project03/python_env/lib/python3.6/site-packages/django/template/loader_tags.py", line 150, in render
    return compiled_parent._render(context)
  File "/home/puy4/CS1XA3/Project03/python_env/lib/python3.6/site-packages/django/template/base.py", line 163, in _render
    return self.nodelist.render(context)
  File "/home/puy4/CS1XA3/Project03/python_env/lib/python3.6/site-packages/django/template/base.py", line 937, in render
    bit = node.render_annotated(context)
  File "/home/puy4/CS1XA3/Project03/python_env/lib/python3.6/site-packages/django/template/base.py", line 904, in render_annotated
    return self.render(context)
  File "/home/puy4/CS1XA3/Project03/python_env/lib/python3.6/site-packages/django/template/loader_tags.py", line 62, in render
    result = block.nodelist.render(context)
  File "/home/puy4/CS1XA3/Project03/python_env/lib/python3.6/site-packages/django/template/base.py", line 937, in render
    bit = node.render_annotated(context)
  File "/home/puy4/CS1XA3/Project03/python_env/lib/python3.6/site-packages/django/template/base.py", line 904, in render_annotated
    return self.render(context)
  File "/home/puy4/CS1XA3/Project03/python_env/lib/python3.6/site-packages/django/template/defaulttags.py", line 443, in render
    url = reverse(view_name, args=args, kwargs=kwargs, current_app=current_app)
  File "/home/puy4/CS1XA3/Project03/python_env/lib/python3.6/site-packages/django/urls/base.py", line 86, in reverse
    raise NoReverseMatch("%s is not a registered namespace" % key)
django.urls.exceptions.NoReverseMatch: 'users' is not a registered namespace
[24/Apr/2019 04:37:47] "GET /e/puy4/ HTTP/1.1" 500 146338
Internal Server Error: /e/puy4/
Traceback (most recent call last):
  File "/home/puy4/CS1XA3/Project03/python_env/lib/python3.6/site-packages/django/urls/base.py", line 75, in reverse
    extra, resolver = resolver.namespace_dict[ns]
KeyError: 'Users'

During handling of the above exception, another exception occurred:

Traceback (most recent call last):
  File "/home/puy4/CS1XA3/Project03/python_env/lib/python3.6/site-packages/django/core/handlers/exception.py", line 34, in inner
    response = get_response(request)
  File "/home/puy4/CS1XA3/Project03/python_env/lib/python3.6/site-packages/django/core/handlers/base.py", line 115, in _get_response
    response = self.process_exception_by_middleware(e, request)
  File "/home/puy4/CS1XA3/Project03/python_env/lib/python3.6/site-packages/django/core/handlers/base.py", line 113, in _get_response
    response = wrapped_callback(request, *callback_args, **callback_kwargs)
  File "/home/puy4/CS1XA3/Project03/django_project/homepage1/views.py", line 9, in home
    return render(request, 'home.html', hometitle)
  File "/home/puy4/CS1XA3/Project03/python_env/lib/python3.6/site-packages/django/shortcuts.py", line 36, in render
    content = loader.render_to_string(template_name, context, request, using=using)
  File "/home/puy4/CS1XA3/Project03/python_env/lib/python3.6/site-packages/django/template/loader.py", line 62, in render_to_string
    return template.render(context, request)
  File "/home/puy4/CS1XA3/Project03/python_env/lib/python3.6/site-packages/django/template/backends/django.py", line 61, in render
    return self.template.render(context)
  File "/home/puy4/CS1XA3/Project03/python_env/lib/python3.6/site-packages/django/template/base.py", line 171, in render
    return self._render(context)
  File "/home/puy4/CS1XA3/Project03/python_env/lib/python3.6/site-packages/django/template/base.py", line 163, in _render
    return self.nodelist.render(context)
  File "/home/puy4/CS1XA3/Project03/python_env/lib/python3.6/site-packages/django/template/base.py", line 937, in render
    bit = node.render_annotated(context)
  File "/home/puy4/CS1XA3/Project03/python_env/lib/python3.6/site-packages/django/template/base.py", line 904, in render_annotated
    return self.render(context)
  File "/home/puy4/CS1XA3/Project03/python_env/lib/python3.6/site-packages/django/template/loader_tags.py", line 150, in render
    return compiled_parent._render(context)
  File "/home/puy4/CS1XA3/Project03/python_env/lib/python3.6/site-packages/django/template/base.py", line 163, in _render
    return self.nodelist.render(context)
  File "/home/puy4/CS1XA3/Project03/python_env/lib/python3.6/site-packages/django/template/base.py", line 937, in render
    bit = node.render_annotated(context)
  File "/home/puy4/CS1XA3/Project03/python_env/lib/python3.6/site-packages/django/template/base.py", line 904, in render_annotated
    return self.render(context)
  File "/home/puy4/CS1XA3/Project03/python_env/lib/python3.6/site-packages/django/template/loader_tags.py", line 62, in render
    result = block.nodelist.render(context)
  File "/home/puy4/CS1XA3/Project03/python_env/lib/python3.6/site-packages/django/template/base.py", line 937, in render
    bit = node.render_annotated(context)
  File "/home/puy4/CS1XA3/Project03/python_env/lib/python3.6/site-packages/django/template/base.py", line 904, in render_annotated
    return self.render(context)
  File "/home/puy4/CS1XA3/Project03/python_env/lib/python3.6/site-packages/django/template/defaulttags.py", line 443, in render
    url = reverse(view_name, args=args, kwargs=kwargs, current_app=current_app)
  File "/home/puy4/CS1XA3/Project03/python_env/lib/python3.6/site-packages/django/urls/base.py", line 86, in reverse
    raise NoReverseMatch("%s is not a registered namespace" % key)
django.urls.exceptions.NoReverseMatch: 'Users' is not a registered namespace
[24/Apr/2019 04:37:59] "GET /e/puy4/ HTTP/1.1" 500 146338
Internal Server Error: /e/puy4/
Traceback (most recent call last):
  File "/home/puy4/CS1XA3/Project03/python_env/lib/python3.6/site-packages/django/urls/base.py", line 75, in reverse
    extra, resolver = resolver.namespace_dict[ns]
KeyError: 'ssers'

During handling of the above exception, another exception occurred:

Traceback (most recent call last):
  File "/home/puy4/CS1XA3/Project03/python_env/lib/python3.6/site-packages/django/core/handlers/exception.py", line 34, in inner
    response = get_response(request)
  File "/home/puy4/CS1XA3/Project03/python_env/lib/python3.6/site-packages/django/core/handlers/base.py", line 115, in _get_response
    response = self.process_exception_by_middleware(e, request)
  File "/home/puy4/CS1XA3/Project03/python_env/lib/python3.6/site-packages/django/core/handlers/base.py", line 113, in _get_response
    response = wrapped_callback(request, *callback_args, **callback_kwargs)
  File "/home/puy4/CS1XA3/Project03/django_project/homepage1/views.py", line 9, in home
    return render(request, 'home.html', hometitle)
  File "/home/puy4/CS1XA3/Project03/python_env/lib/python3.6/site-packages/django/shortcuts.py", line 36, in render
    content = loader.render_to_string(template_name, context, request, using=using)
  File "/home/puy4/CS1XA3/Project03/python_env/lib/python3.6/site-packages/django/template/loader.py", line 62, in render_to_string
    return template.render(context, request)
  File "/home/puy4/CS1XA3/Project03/python_env/lib/python3.6/site-packages/django/template/backends/django.py", line 61, in render
    return self.template.render(context)
  File "/home/puy4/CS1XA3/Project03/python_env/lib/python3.6/site-packages/django/template/base.py", line 171, in render
    return self._render(context)
  File "/home/puy4/CS1XA3/Project03/python_env/lib/python3.6/site-packages/django/template/base.py", line 163, in _render
    return self.nodelist.render(context)
  File "/home/puy4/CS1XA3/Project03/python_env/lib/python3.6/site-packages/django/template/base.py", line 937, in render
    bit = node.render_annotated(context)
  File "/home/puy4/CS1XA3/Project03/python_env/lib/python3.6/site-packages/django/template/base.py", line 904, in render_annotated
    return self.render(context)
  File "/home/puy4/CS1XA3/Project03/python_env/lib/python3.6/site-packages/django/template/loader_tags.py", line 150, in render
    return compiled_parent._render(context)
  File "/home/puy4/CS1XA3/Project03/python_env/lib/python3.6/site-packages/django/template/base.py", line 163, in _render
    return self.nodelist.render(context)
  File "/home/puy4/CS1XA3/Project03/python_env/lib/python3.6/site-packages/django/template/base.py", line 937, in render
    bit = node.render_annotated(context)
  File "/home/puy4/CS1XA3/Project03/python_env/lib/python3.6/site-packages/django/template/base.py", line 904, in render_annotated
    return self.render(context)
  File "/home/puy4/CS1XA3/Project03/python_env/lib/python3.6/site-packages/django/template/loader_tags.py", line 62, in render
    result = block.nodelist.render(context)
  File "/home/puy4/CS1XA3/Project03/python_env/lib/python3.6/site-packages/django/template/base.py", line 937, in render
    bit = node.render_annotated(context)
  File "/home/puy4/CS1XA3/Project03/python_env/lib/python3.6/site-packages/django/template/base.py", line 904, in render_annotated
    return self.render(context)
  File "/home/puy4/CS1XA3/Project03/python_env/lib/python3.6/site-packages/django/template/defaulttags.py", line 443, in render
    url = reverse(view_name, args=args, kwargs=kwargs, current_app=current_app)
  File "/home/puy4/CS1XA3/Project03/python_env/lib/python3.6/site-packages/django/urls/base.py", line 86, in reverse
    raise NoReverseMatch("%s is not a registered namespace" % key)
django.urls.exceptions.NoReverseMatch: 'ssers' is not a registered namespace
[24/Apr/2019 04:38:15] "GET /e/puy4/ HTTP/1.1" 500 146373
Internal Server Error: /e/puy4/
Traceback (most recent call last):
  File "/home/puy4/CS1XA3/Project03/python_env/lib/python3.6/site-packages/django/urls/base.py", line 75, in reverse
    extra, resolver = resolver.namespace_dict[ns]
KeyError: 'users'

During handling of the above exception, another exception occurred:

Traceback (most recent call last):
  File "/home/puy4/CS1XA3/Project03/python_env/lib/python3.6/site-packages/django/core/handlers/exception.py", line 34, in inner
    response = get_response(request)
  File "/home/puy4/CS1XA3/Project03/python_env/lib/python3.6/site-packages/django/core/handlers/base.py", line 115, in _get_response
    response = self.process_exception_by_middleware(e, request)
  File "/home/puy4/CS1XA3/Project03/python_env/lib/python3.6/site-packages/django/core/handlers/base.py", line 113, in _get_response
    response = wrapped_callback(request, *callback_args, **callback_kwargs)
  File "/home/puy4/CS1XA3/Project03/django_project/homepage1/views.py", line 9, in home
    return render(request, 'home.html', hometitle)
  File "/home/puy4/CS1XA3/Project03/python_env/lib/python3.6/site-packages/django/shortcuts.py", line 36, in render
    content = loader.render_to_string(template_name, context, request, using=using)
  File "/home/puy4/CS1XA3/Project03/python_env/lib/python3.6/site-packages/django/template/loader.py", line 62, in render_to_string
    return template.render(context, request)
  File "/home/puy4/CS1XA3/Project03/python_env/lib/python3.6/site-packages/django/template/backends/django.py", line 61, in render
    return self.template.render(context)
  File "/home/puy4/CS1XA3/Project03/python_env/lib/python3.6/site-packages/django/template/base.py", line 171, in render
    return self._render(context)
  File "/home/puy4/CS1XA3/Project03/python_env/lib/python3.6/site-packages/django/template/base.py", line 163, in _render
    return self.nodelist.render(context)
  File "/home/puy4/CS1XA3/Project03/python_env/lib/python3.6/site-packages/django/template/base.py", line 937, in render
    bit = node.render_annotated(context)
  File "/home/puy4/CS1XA3/Project03/python_env/lib/python3.6/site-packages/django/template/base.py", line 904, in render_annotated
    return self.render(context)
  File "/home/puy4/CS1XA3/Project03/python_env/lib/python3.6/site-packages/django/template/loader_tags.py", line 150, in render
    return compiled_parent._render(context)
  File "/home/puy4/CS1XA3/Project03/python_env/lib/python3.6/site-packages/django/template/base.py", line 163, in _render
    return self.nodelist.render(context)
  File "/home/puy4/CS1XA3/Project03/python_env/lib/python3.6/site-packages/django/template/base.py", line 937, in render
    bit = node.render_annotated(context)
  File "/home/puy4/CS1XA3/Project03/python_env/lib/python3.6/site-packages/django/template/base.py", line 904, in render_annotated
    return self.render(context)
  File "/home/puy4/CS1XA3/Project03/python_env/lib/python3.6/site-packages/django/template/loader_tags.py", line 62, in render
    result = block.nodelist.render(context)
  File "/home/puy4/CS1XA3/Project03/python_env/lib/python3.6/site-packages/django/template/base.py", line 937, in render
    bit = node.render_annotated(context)
  File "/home/puy4/CS1XA3/Project03/python_env/lib/python3.6/site-packages/django/template/base.py", line 904, in render_annotated
    return self.render(context)
  File "/home/puy4/CS1XA3/Project03/python_env/lib/python3.6/site-packages/django/template/defaulttags.py", line 443, in render
    url = reverse(view_name, args=args, kwargs=kwargs, current_app=current_app)
  File "/home/puy4/CS1XA3/Project03/python_env/lib/python3.6/site-packages/django/urls/base.py", line 86, in reverse
    raise NoReverseMatch("%s is not a registered namespace" % key)
django.urls.exceptions.NoReverseMatch: 'users' is not a registered namespace
[24/Apr/2019 04:38:32] "GET /e/puy4/ HTTP/1.1" 500 146373
[24/Apr/2019 04:41:15] "GET /e/puy4/ HTTP/1.1" 200 1450
/home/puy4/CS1XA3/Project03/django_project/homepage1/views.py changed, reloading.
Performing system checks...

System check identified no issues (0 silenced).
April 24, 2019 - 04:20:45
Django version 2.2, using settings 'django_project.settings'
Starting development server at http://localhost:10048/
Quit the server with CONTROL-C.
Watching for file changes with StatReloader
/home/puy4/CS1XA3/Project03/django_project/homepage1/views.py changed, reloading.
Performing system checks...

System check identified no issues (0 silenced).
April 24, 2019 - 04:45:34
Django version 2.2, using settings 'django_project.settings'
Starting development server at http://localhost:10048/
Quit the server with CONTROL-C.
Watching for file changes with StatReloader
[24/Apr/2019 04:53:07] "GET /e/puy4/ HTTP/1.1" 200 1445
[24/Apr/2019 04:53:21] "GET /e/puy4/ HTTP/1.1" 200 1451
Not Found: /e/puy4/e/puy4/login
[24/Apr/2019 04:53:22] "GET /e/puy4/e/puy4/login HTTP/1.1" 404 2742
Not Found: /e/puy4/e/puy4/login
[24/Apr/2019 04:53:32] "GET /e/puy4/e/puy4/login HTTP/1.1" 404 2742
Not Found: /e/puy4/e/puy4/login
[24/Apr/2019 04:53:37] "GET /e/puy4/e/puy4/login HTTP/1.1" 404 2742
Not Found: /e/puy4/e/puy4/login
[24/Apr/2019 04:53:39] "GET /e/puy4/e/puy4/login HTTP/1.1" 404 2742
Not Found: /e/puy4/e/puy4/login
[24/Apr/2019 04:53:42] "GET /e/puy4/e/puy4/login HTTP/1.1" 404 2742
[24/Apr/2019 04:54:12] "GET /e/puy4/ HTTP/1.1" 200 1407
[24/Apr/2019 04:54:38] "GET /e/puy4/ HTTP/1.1" 200 1408
Not Found: /e/puy4/*/login
[24/Apr/2019 04:54:39] "GET /e/puy4/*/login HTTP/1.1" 404 2727
Not Found: /e/puy4/*/login
[24/Apr/2019 04:54:47] "GET /e/puy4/*/login HTTP/1.1" 404 2727
[24/Apr/2019 04:54:59] "GET /e/puy4/ HTTP/1.1" 200 1406
[24/Apr/2019 04:55:00] "GET /e/puy4/login HTTP/1.1" 301 0
[24/Apr/2019 04:55:00] "GET /e/puy4/login/ HTTP/1.1" 200 1589
[24/Apr/2019 04:55:45] "GET /e/puy4/ HTTP/1.1" 200 1353
[24/Apr/2019 04:55:46] "GET /e/puy4/login/ HTTP/1.1" 200 1589
[24/Apr/2019 04:56:09] "GET /e/puy4/ HTTP/1.1" 200 1343
/home/puy4/CS1XA3/Project03/django_project/homepage1/views.py changed, reloading.
Performing system checks...

System check identified no issues (0 silenced).
April 24, 2019 - 04:51:07
Django version 2.2, using settings 'django_project.settings'
Starting development server at http://localhost:10048/
Quit the server with CONTROL-C.
Watching for file changes with StatReloader
Performing system checks...

Traceback (most recent call last):
  File "manage.py", line 21, in <module>
    main()
  File "manage.py", line 17, in main
    execute_from_command_line(sys.argv)
  File "/home/puy4/CS1XA3/Project03/python_env/lib/python3.6/site-packages/django/core/management/__init__.py", line 381, in execute_from_command_line
    utility.execute()
  File "/home/puy4/CS1XA3/Project03/python_env/lib/python3.6/site-packages/django/core/management/__init__.py", line 375, in execute
    self.fetch_command(subcommand).run_from_argv(self.argv)
  File "/home/puy4/CS1XA3/Project03/python_env/lib/python3.6/site-packages/django/core/management/base.py", line 323, in run_from_argv
    self.execute(*args, **cmd_options)
  File "/home/puy4/CS1XA3/Project03/python_env/lib/python3.6/site-packages/django/core/management/commands/runserver.py", line 60, in execute
    super().execute(*args, **options)
  File "/home/puy4/CS1XA3/Project03/python_env/lib/python3.6/site-packages/django/core/management/base.py", line 364, in execute
    output = self.handle(*args, **options)
  File "/home/puy4/CS1XA3/Project03/python_env/lib/python3.6/site-packages/django/core/management/commands/runserver.py", line 95, in handle
    self.run(**options)
  File "/home/puy4/CS1XA3/Project03/python_env/lib/python3.6/site-packages/django/core/management/commands/runserver.py", line 102, in run
    autoreload.run_with_reloader(self.inner_run, **options)
  File "/home/puy4/CS1XA3/Project03/python_env/lib/python3.6/site-packages/django/utils/autoreload.py", line 579, in run_with_reloader
    start_django(reloader, main_func, *args, **kwargs)
  File "/home/puy4/CS1XA3/Project03/python_env/lib/python3.6/site-packages/django/utils/autoreload.py", line 564, in start_django
    reloader.run(django_main_thread)
  File "/home/puy4/CS1XA3/Project03/python_env/lib/python3.6/site-packages/django/utils/autoreload.py", line 272, in run
    get_resolver().urlconf_module
  File "/home/puy4/CS1XA3/Project03/python_env/lib/python3.6/site-packages/django/utils/functional.py", line 80, in __get__
    res = instance.__dict__[self.name] = self.func(instance)
  File "/home/puy4/CS1XA3/Project03/python_env/lib/python3.6/site-packages/django/urls/resolvers.py", line 564, in urlconf_module
    return import_module(self.urlconf_name)
  File "/usr/lib/python3.6/importlib/__init__.py", line 126, in import_module
    return _bootstrap._gcd_import(name[level:], package, level)
  File "<frozen importlib._bootstrap>", line 994, in _gcd_import
  File "<frozen importlib._bootstrap>", line 971, in _find_and_load
  File "<frozen importlib._bootstrap>", line 955, in _find_and_load_unlocked
  File "<frozen importlib._bootstrap>", line 665, in _load_unlocked
  File "<frozen importlib._bootstrap_external>", line 678, in exec_module
  File "<frozen importlib._bootstrap>", line 219, in _call_with_frames_removed
  File "/home/puy4/CS1XA3/Project03/django_project/django_project/urls.py", line 25, in <module>
    path('e/puy4/', include('homepage1.urls')),
  File "/home/puy4/CS1XA3/Project03/python_env/lib/python3.6/site-packages/django/urls/conf.py", line 34, in include
    urlconf_module = import_module(urlconf_module)
  File "/usr/lib/python3.6/importlib/__init__.py", line 126, in import_module
    return _bootstrap._gcd_import(name[level:], package, level)
  File "<frozen importlib._bootstrap>", line 994, in _gcd_import
  File "<frozen importlib._bootstrap>", line 971, in _find_and_load
  File "<frozen importlib._bootstrap>", line 955, in _find_and_load_unlocked
  File "<frozen importlib._bootstrap>", line 665, in _load_unlocked
  File "<frozen importlib._bootstrap_external>", line 678, in exec_module
  File "<frozen importlib._bootstrap>", line 219, in _call_with_frames_removed
  File "/home/puy4/CS1XA3/Project03/django_project/homepage1/urls.py", line 2, in <module>
    from . import views
  File "/home/puy4/CS1XA3/Project03/django_project/homepage1/views.py", line 17
    input = 
           ^
SyntaxError: invalid syntax
Watching for file changes with StatReloader
Performing system checks...

Traceback (most recent call last):
  File "manage.py", line 21, in <module>
    main()
  File "manage.py", line 17, in main
    execute_from_command_line(sys.argv)
  File "/home/puy4/CS1XA3/Project03/python_env/lib/python3.6/site-packages/django/core/management/__init__.py", line 381, in execute_from_command_line
    utility.execute()
  File "/home/puy4/CS1XA3/Project03/python_env/lib/python3.6/site-packages/django/core/management/__init__.py", line 375, in execute
    self.fetch_command(subcommand).run_from_argv(self.argv)
  File "/home/puy4/CS1XA3/Project03/python_env/lib/python3.6/site-packages/django/core/management/base.py", line 323, in run_from_argv
    self.execute(*args, **cmd_options)
  File "/home/puy4/CS1XA3/Project03/python_env/lib/python3.6/site-packages/django/core/management/commands/runserver.py", line 60, in execute
    super().execute(*args, **options)
  File "/home/puy4/CS1XA3/Project03/python_env/lib/python3.6/site-packages/django/core/management/base.py", line 364, in execute
    output = self.handle(*args, **options)
  File "/home/puy4/CS1XA3/Project03/python_env/lib/python3.6/site-packages/django/core/management/commands/runserver.py", line 95, in handle
    self.run(**options)
  File "/home/puy4/CS1XA3/Project03/python_env/lib/python3.6/site-packages/django/core/management/commands/runserver.py", line 102, in run
    autoreload.run_with_reloader(self.inner_run, **options)
  File "/home/puy4/CS1XA3/Project03/python_env/lib/python3.6/site-packages/django/utils/autoreload.py", line 579, in run_with_reloader
    start_django(reloader, main_func, *args, **kwargs)
  File "/home/puy4/CS1XA3/Project03/python_env/lib/python3.6/site-packages/django/utils/autoreload.py", line 564, in start_django
    reloader.run(django_main_thread)
  File "/home/puy4/CS1XA3/Project03/python_env/lib/python3.6/site-packages/django/utils/autoreload.py", line 272, in run
    get_resolver().urlconf_module
  File "/home/puy4/CS1XA3/Project03/python_env/lib/python3.6/site-packages/django/utils/functional.py", line 80, in __get__
    res = instance.__dict__[self.name] = self.func(instance)
  File "/home/puy4/CS1XA3/Project03/python_env/lib/python3.6/site-packages/django/urls/resolvers.py", line 564, in urlconf_module
    return import_module(self.urlconf_name)
  File "/usr/lib/python3.6/importlib/__init__.py", line 126, in import_module
    return _bootstrap._gcd_import(name[level:], package, level)
  File "<frozen importlib._bootstrap>", line 994, in _gcd_import
Exception in thread Thread-1:
Traceback (most recent call last):
  File "/usr/lib/python3.6/threading.py", line 916, in _bootstrap_inner
    self.run()
  File "/usr/lib/python3.6/threading.py", line 864, in run
    self._target(*self._args, **self._kwargs)
  File "/home/puy4/CS1XA3/Project03/python_env/lib/python3.6/site-packages/django/utils/autoreload.py", line 54, in wrapper
    fn(*args, **kwargs)
  File "/home/puy4/CS1XA3/Project03/python_env/lib/python3.6/site-packages/django/core/management/commands/runserver.py", line 117, in inner_run
    self.check(display_num_errors=True)
  File "/home/puy4/CS1XA3/Project03/python_env/lib/python3.6/site-packages/django/core/management/base.py", line 390, in check
    include_deployment_checks=include_deployment_checks,
  File "/home/puy4/CS1XA3/Project03/python_env/lib/python3.6/site-packages/django/core/management/base.py", line 377, in _run_checks
    return checks.run_checks(**kwargs)
  File "/home/puy4/CS1XA3/Project03/python_env/lib/python3.6/site-packages/django/core/checks/registry.py", line 72, in run_checks
    new_errors = check(app_configs=app_configs)
  File "/home/puy4/CS1XA3/Project03/python_env/lib/python3.6/site-packages/django/core/checks/urls.py", line 40, in check_url_namespaces_unique
    all_namespaces = _load_all_namespaces(resolver)
  File "/home/puy4/CS1XA3/Project03/python_env/lib/python3.6/site-packages/django/core/checks/urls.py", line 57, in _load_all_namespaces
    url_patterns = getattr(resolver, 'url_patterns', [])
  File "/home/puy4/CS1XA3/Project03/python_env/lib/python3.6/site-packages/django/utils/functional.py", line 80, in __get__
    res = instance.__dict__[self.name] = self.func(instance)
  File "/home/puy4/CS1XA3/Project03/python_env/lib/python3.6/site-packages/django/urls/resolvers.py", line 571, in url_patterns
    patterns = getattr(self.urlconf_module, "urlpatterns", self.urlconf_module)
  File "/home/puy4/CS1XA3/Project03/python_env/lib/python3.6/site-packages/django/utils/functional.py", line 80, in __get__
    res = instance.__dict__[self.name] = self.func(instance)
  File "/home/puy4/CS1XA3/Project03/python_env/lib/python3.6/site-packages/django/urls/resolvers.py", line 564, in urlconf_module
    return import_module(self.urlconf_name)
  File "/usr/lib/python3.6/importlib/__init__.py", line 126, in import_module
    return _bootstrap._gcd_import(name[level:], package, level)
  File "<frozen importlib._bootstrap>", line 994, in _gcd_import
  File "<frozen importlib._bootstrap>", line 971, in _find_and_load
  File "<frozen importlib._bootstrap>", line 955, in _find_and_load_unlocked
  File "<frozen importlib._bootstrap>", line 665, in _load_unlocked
  File "<frozen importlib._bootstrap_external>", line 678, in exec_module
  File "<frozen importlib._bootstrap>", line 219, in _call_with_frames_removed
  File "/home/puy4/CS1XA3/Project03/django_project/django_project/urls.py", line 25, in <module>
    path('e/puy4/', include('homepage1.urls')),
  File "/home/puy4/CS1XA3/Project03/python_env/lib/python3.6/site-packages/django/urls/conf.py", line 34, in include
    urlconf_module = import_module(urlconf_module)
  File "/usr/lib/python3.6/importlib/__init__.py", line 126, in import_module
    return _bootstrap._gcd_import(name[level:], package, level)
  File "<frozen importlib._bootstrap>", line 994, in _gcd_import
  File "<frozen importlib._bootstrap>", line 971, in _find_and_load
  File "<frozen importlib._bootstrap>", line 955, in _find_and_load_unlocked
  File "<frozen importlib._bootstrap>", line 665, in _load_unlocked
  File "<frozen importlib._bootstrap_external>", line 678, in exec_module
  File "<frozen importlib._bootstrap>", line 219, in _call_with_frames_removed
  File "/home/puy4/CS1XA3/Project03/django_project/homepage1/urls.py", line 2, in <module>
    from . import views
  File "/home/puy4/CS1XA3/Project03/django_project/homepage1/views.py", line 17
    input =
           ^
SyntaxError: invalid syntax

  File "<frozen importlib._bootstrap>", line 971, in _find_and_load
  File "<frozen importlib._bootstrap>", line 955, in _find_and_load_unlocked
  File "<frozen importlib._bootstrap>", line 665, in _load_unlocked
  File "<frozen importlib._bootstrap_external>", line 678, in exec_module
  File "<frozen importlib._bootstrap>", line 219, in _call_with_frames_removed
  File "/home/puy4/CS1XA3/Project03/django_project/django_project/urls.py", line 25, in <module>
    path('e/puy4/', include('homepage1.urls')),
  File "/home/puy4/CS1XA3/Project03/python_env/lib/python3.6/site-packages/django/urls/conf.py", line 34, in include
    urlconf_module = import_module(urlconf_module)
  File "/usr/lib/python3.6/importlib/__init__.py", line 126, in import_module
    return _bootstrap._gcd_import(name[level:], package, level)
  File "<frozen importlib._bootstrap>", line 994, in _gcd_import
  File "<frozen importlib._bootstrap>", line 971, in _find_and_load
  File "<frozen importlib._bootstrap>", line 955, in _find_and_load_unlocked
  File "<frozen importlib._bootstrap>", line 665, in _load_unlocked
  File "<frozen importlib._bootstrap_external>", line 678, in exec_module
  File "<frozen importlib._bootstrap>", line 219, in _call_with_frames_removed
  File "/home/puy4/CS1XA3/Project03/django_project/homepage1/urls.py", line 2, in <module>
    from . import views
  File "/home/puy4/CS1XA3/Project03/django_project/homepage1/views.py", line 17
    input = 
           ^
SyntaxError: invalid syntax
Watching for file changes with StatReloader
Performing system checks...

Traceback (most recent call last):
  File "manage.py", line 21, in <module>
    main()
  File "manage.py", line 17, in main
    execute_from_command_line(sys.argv)
  File "/home/puy4/CS1XA3/Project03/python_env/lib/python3.6/site-packages/django/core/management/__init__.py", line 381, in execute_from_command_line
    utility.execute()
  File "/home/puy4/CS1XA3/Project03/python_env/lib/python3.6/site-packages/django/core/management/__init__.py", line 375, in execute
    self.fetch_command(subcommand).run_from_argv(self.argv)
  File "/home/puy4/CS1XA3/Project03/python_env/lib/python3.6/site-packages/django/core/management/base.py", line 323, in run_from_argv
    self.execute(*args, **cmd_options)
  File "/home/puy4/CS1XA3/Project03/python_env/lib/python3.6/site-packages/django/core/management/commands/runserver.py", line 60, in execute
    super().execute(*args, **options)
  File "/home/puy4/CS1XA3/Project03/python_env/lib/python3.6/site-packages/django/core/management/base.py", line 364, in execute
    output = self.handle(*args, **options)
  File "/home/puy4/CS1XA3/Project03/python_env/lib/python3.6/site-packages/django/core/management/commands/runserver.py", line 95, in handle
    self.run(**options)
  File "/home/puy4/CS1XA3/Project03/python_env/lib/python3.6/site-packages/django/core/management/commands/runserver.py", line 102, in run
    autoreload.run_with_reloader(self.inner_run, **options)
  File "/home/puy4/CS1XA3/Project03/python_env/lib/python3.6/site-packages/django/utils/autoreload.py", line 579, in run_with_reloader
    start_django(reloader, main_func, *args, **kwargs)
  File "/home/puy4/CS1XA3/Project03/python_env/lib/python3.6/site-packages/django/utils/autoreload.py", line 564, in start_django
    reloader.run(django_main_thread)
  File "/home/puy4/CS1XA3/Project03/python_env/lib/python3.6/site-packages/django/utils/autoreload.py", line 272, in run
    get_resolver().urlconf_module
  File "/home/puy4/CS1XA3/Project03/python_env/lib/python3.6/site-packages/django/utils/functional.py", line 80, in __get__
    res = instance.__dict__[self.name] = self.func(instance)
  File "/home/puy4/CS1XA3/Project03/python_env/lib/python3.6/site-packages/django/urls/resolvers.py", line 564, in urlconf_module
    return import_module(self.urlconf_name)
  File "/usr/lib/python3.6/importlib/__init__.py", line 126, in import_module
    return _bootstrap._gcd_import(name[level:], package, level)
  File "<frozen importlib._bootstrap>", line 994, in _gcd_import
  File "<frozen importlib._bootstrap>", line 971, in _find_and_load
  File "<frozen importlib._bootstrap>", line 955, in _find_and_load_unlocked
Exception in thread Thread-1:
Traceback (most recent call last):
  File "/usr/lib/python3.6/threading.py", line 916, in _bootstrap_inner
    self.run()
  File "/usr/lib/python3.6/threading.py", line 864, in run
    self._target(*self._args, **self._kwargs)
  File "/home/puy4/CS1XA3/Project03/python_env/lib/python3.6/site-packages/django/utils/autoreload.py", line 54, in wrapper
    fn(*args, **kwargs)
  File "/home/puy4/CS1XA3/Project03/python_env/lib/python3.6/site-packages/django/core/management/commands/runserver.py", line 117, in inner_run
    self.check(display_num_errors=True)
  File "/home/puy4/CS1XA3/Project03/python_env/lib/python3.6/site-packages/django/core/management/base.py", line 390, in check
    include_deployment_checks=include_deployment_checks,
  File "/home/puy4/CS1XA3/Project03/python_env/lib/python3.6/site-packages/django/core/management/base.py", line 377, in _run_checks
    return checks.run_checks(**kwargs)
  File "/home/puy4/CS1XA3/Project03/python_env/lib/python3.6/site-packages/django/core/checks/registry.py", line 72, in run_checks
    new_errors = check(app_configs=app_configs)
  File "/home/puy4/CS1XA3/Project03/python_env/lib/python3.6/site-packages/django/core/checks/urls.py", line 13, in check_url_config
    return check_resolver(resolver)
  File "/home/puy4/CS1XA3/Project03/python_env/lib/python3.6/site-packages/django/core/checks/urls.py", line 23, in check_resolver
    return check_method()
  File "/home/puy4/CS1XA3/Project03/python_env/lib/python3.6/site-packages/django/urls/resolvers.py", line 398, in check
    for pattern in self.url_patterns:
  File "/home/puy4/CS1XA3/Project03/python_env/lib/python3.6/site-packages/django/utils/functional.py", line 80, in __get__
    res = instance.__dict__[self.name] = self.func(instance)
  File "/home/puy4/CS1XA3/Project03/python_env/lib/python3.6/site-packages/django/urls/resolvers.py", line 571, in url_patterns
    patterns = getattr(self.urlconf_module, "urlpatterns", self.urlconf_module)
  File "/home/puy4/CS1XA3/Project03/python_env/lib/python3.6/site-packages/django/utils/functional.py", line 80, in __get__
    res = instance.__dict__[self.name] = self.func(instance)
  File "/home/puy4/CS1XA3/Project03/python_env/lib/python3.6/site-packages/django/urls/resolvers.py", line 564, in urlconf_module
    return import_module(self.urlconf_name)
  File "/usr/lib/python3.6/importlib/__init__.py", line 126, in import_module
    return _bootstrap._gcd_import(name[level:], package, level)
  File "<frozen importlib._bootstrap>", line 994, in _gcd_import
  File "<frozen importlib._bootstrap>", line 971, in _find_and_load
  File "<frozen importlib._bootstrap>", line 955, in _find_and_load_unlocked
  File "<frozen importlib._bootstrap>", line 665, in _load_unlocked
  File "<frozen importlib._bootstrap_external>", line 678, in exec_module
  File "<frozen importlib._bootstrap>", line 219, in _call_with_frames_removed
  File "/home/puy4/CS1XA3/Project03/django_project/django_project/urls.py", line 25, in <module>
    path('e/puy4/', include('homepage1.urls')),
  File "/home/puy4/CS1XA3/Project03/python_env/lib/python3.6/site-packages/django/urls/conf.py", line 34, in include
    urlconf_module = import_module(urlconf_module)
  File "/usr/lib/python3.6/importlib/__init__.py", line 126, in import_module
    return _bootstrap._gcd_import(name[level:], package, level)
  File "<frozen importlib._bootstrap>", line 994, in _gcd_import
  File "<frozen importlib._bootstrap>", line 971, in _find_and_load
  File "<frozen importlib._bootstrap>", line 955, in _find_and_load_unlocked
  File "<frozen importlib._bootstrap>", line 665, in _load_unlocked
  File "<frozen importlib._bootstrap_external>", line 678, in exec_module
  File "<frozen importlib._bootstrap>", line 219, in _call_with_frames_removed
  File "/home/puy4/CS1XA3/Project03/django_project/homepage1/urls.py", line 2, in <module>
    from . import views
  File "/home/puy4/CS1XA3/Project03/django_project/homepage1/views.py", line 15
    ‘’‘def notesinput(request):
         ^
SyntaxError: invalid character in identifier

  File "<frozen importlib._bootstrap>", line 665, in _load_unlocked
  File "<frozen importlib._bootstrap_external>", line 678, in exec_module
  File "<frozen importlib._bootstrap>", line 219, in _call_with_frames_removed
  File "/home/puy4/CS1XA3/Project03/django_project/django_project/urls.py", line 25, in <module>
    path('e/puy4/', include('homepage1.urls')),
  File "/home/puy4/CS1XA3/Project03/python_env/lib/python3.6/site-packages/django/urls/conf.py", line 34, in include
    urlconf_module = import_module(urlconf_module)
  File "/usr/lib/python3.6/importlib/__init__.py", line 126, in import_module
    return _bootstrap._gcd_import(name[level:], package, level)
  File "<frozen importlib._bootstrap>", line 994, in _gcd_import
  File "<frozen importlib._bootstrap>", line 971, in _find_and_load
  File "<frozen importlib._bootstrap>", line 955, in _find_and_load_unlocked
  File "<frozen importlib._bootstrap>", line 665, in _load_unlocked
  File "<frozen importlib._bootstrap_external>", line 678, in exec_module
  File "<frozen importlib._bootstrap>", line 219, in _call_with_frames_removed
  File "/home/puy4/CS1XA3/Project03/django_project/homepage1/urls.py", line 2, in <module>
    from . import views
  File "/home/puy4/CS1XA3/Project03/django_project/homepage1/views.py", line 15
    ‘’‘def notesinput(request):
         ^
SyntaxError: invalid character in identifier
Watching for file changes with StatReloader
[24/Apr/2019 05:13:31] "GET /e/puy4/ HTTP/1.1" 200 1343
[24/Apr/2019 05:13:32] "GET /e/puy4/login/ HTTP/1.1" 200 1589
[24/Apr/2019 05:13:34] "POST /e/puy4/login/ HTTP/1.1" 302 0
[24/Apr/2019 05:13:34] "GET /e/puy4/notes/ HTTP/1.1" 200 1552
[24/Apr/2019 05:15:34] "GET /e/puy4/notes/ HTTP/1.1" 200 1552
[24/Apr/2019 05:15:35] "GET /e/puy4/login/ HTTP/1.1" 200 1589
Not Found: /e/puy4/ladmin
[24/Apr/2019 05:15:40] "GET /e/puy4/ladmin HTTP/1.1" 404 2724
[24/Apr/2019 05:15:44] "GET /e/puy4/admin HTTP/1.1" 301 0
[24/Apr/2019 05:15:44] "GET /e/puy4/admin/ HTTP/1.1" 200 4164
[24/Apr/2019 05:15:44] "GET /e/puy4/static/admin/css/base.css HTTP/1.1" 200 16378
[24/Apr/2019 05:15:44] "GET /e/puy4/static/admin/css/dashboard.css HTTP/1.1" 200 412
[24/Apr/2019 05:15:44] "GET /e/puy4/static/admin/css/responsive.css HTTP/1.1" 200 17944
[24/Apr/2019 05:15:44] "GET /e/puy4/admin/ HTTP/1.1" 200 4164
[24/Apr/2019 05:15:45] "GET /e/puy4/static/admin/css/fonts.css HTTP/1.1" 200 423
[24/Apr/2019 05:15:45] "GET /e/puy4/static/admin/img/icon-changelink.svg HTTP/1.1" 200 380
[24/Apr/2019 05:15:45] "GET /e/puy4/static/admin/img/icon-addlink.svg HTTP/1.1" 200 331
[24/Apr/2019 05:15:45] "GET /e/puy4/static/admin/fonts/Roboto-Light-webfont.woff HTTP/1.1" 200 85692
[24/Apr/2019 05:15:45] "GET /e/puy4/static/admin/fonts/Roboto-Regular-webfont.woff HTTP/1.1" 200 85876
[24/Apr/2019 05:15:45] "GET /e/puy4/static/admin/fonts/Roboto-Bold-webfont.woff HTTP/1.1" 200 86184
[24/Apr/2019 05:16:45] "GET /e/puy4/admin/ HTTP/1.1" 200 4164
[24/Apr/2019 05:16:46] "GET /e/puy4/register/ HTTP/1.1" 200 2530
Watching for file changes with StatReloader
[24/Apr/2019 05:17:27] "GET /e/puy4/register/ HTTP/1.1" 200 2530
Watching for file changes with StatReloader
[24/Apr/2019 05:18:13] "GET /e/puy4/register/ HTTP/1.1" 200 2530
[24/Apr/2019 05:18:14] "GET /e/puy4/register/ HTTP/1.1" 200 2530
[24/Apr/2019 05:18:14] "GET /e/puy4/register/ HTTP/1.1" 200 2530
[24/Apr/2019 05:18:14] "GET /e/puy4/register/ HTTP/1.1" 200 2530
/home/puy4/CS1XA3/Project03/django_project/users/views.py changed, reloading.
Performing system checks...

System check identified no issues (0 silenced).
April 24, 2019 - 05:18:03
Django version 2.2, using settings 'django_project.settings'
Starting development server at http://localhost:10048/
Quit the server with CONTROL-C.
Watching for file changes with StatReloader
[24/Apr/2019 05:19:06] "GET /e/puy4/register/ HTTP/1.1" 200 2530
[24/Apr/2019 05:19:16] "POST /e/puy4/register/ HTTP/1.1" 200 2621
[24/Apr/2019 05:19:29] "POST /e/puy4/register/ HTTP/1.1" 302 0
[24/Apr/2019 05:19:29] "GET /e/puy4/login/ HTTP/1.1" 200 1639
[24/Apr/2019 05:23:06] "GET /e/puy4/login/ HTTP/1.1" 200 1726
[24/Apr/2019 05:23:17] "GET /e/puy4/register/ HTTP/1.1" 200 2530
[24/Apr/2019 05:23:19] "GET /e/puy4/login/ HTTP/1.1" 200 1592
/home/puy4/CS1XA3/Project03/django_project/users/views.py changed, reloading.
Performing system checks...

System check identified no issues (0 silenced).
April 24, 2019 - 05:19:02
Django version 2.2, using settings 'django_project.settings'
Starting development server at http://localhost:10048/
Quit the server with CONTROL-C.
Watching for file changes with StatReloader
[24/Apr/2019 05:29:04] "GET /e/puy4/login/ HTTP/1.1" 200 1592
[24/Apr/2019 05:29:06] "GET /e/puy4/register/ HTTP/1.1" 200 2530
[24/Apr/2019 05:29:20] "POST /e/puy4/register/ HTTP/1.1" 302 0
[24/Apr/2019 05:29:20] "GET /e/puy4/login/ HTTP/1.1" 200 1714
[24/Apr/2019 05:30:21] "GET /e/puy4/login/ HTTP/1.1" 200 1592
[24/Apr/2019 05:30:22] "GET /e/puy4/login/ HTTP/1.1" 200 1592
[24/Apr/2019 05:30:24] "GET /e/puy4/register/ HTTP/1.1" 200 2530
[24/Apr/2019 05:30:36] "POST /e/puy4/register/ HTTP/1.1" 200 2626
[24/Apr/2019 05:30:47] "POST /e/puy4/register/ HTTP/1.1" 302 0
[24/Apr/2019 05:30:47] "GET /e/puy4/login/ HTTP/1.1" 200 1739
[24/Apr/2019 05:31:16] "GET /e/puy4/login/ HTTP/1.1" 200 1592
[24/Apr/2019 05:31:21] "GET /e/puy4/register/ HTTP/1.1" 200 2530
[24/Apr/2019 05:31:34] "POST /e/puy4/register/ HTTP/1.1" 302 0
[24/Apr/2019 05:31:34] "GET /e/puy4/login/ HTTP/1.1" 200 1741
[24/Apr/2019 05:35:07] "GET /e/puy4/logout HTTP/1.1" 301 0
[24/Apr/2019 05:35:07] "GET /e/puy4/logout/ HTTP/1.1" 200 1212
[24/Apr/2019 05:36:03] "GET /e/puy4/logout/ HTTP/1.1" 200 1240
Not Found: /e/puy4/logout/home
[24/Apr/2019 05:36:06] "GET /e/puy4/logout/home HTTP/1.1" 404 2739
[24/Apr/2019 05:36:08] "GET /e/puy4/logout/ HTTP/1.1" 200 1240
Not Found: /e/puy4/logout/home
[24/Apr/2019 05:36:09] "GET /e/puy4/logout/home HTTP/1.1" 404 2739
[24/Apr/2019 05:36:12] "GET /e/puy4/logout/ HTTP/1.1" 200 1240
[24/Apr/2019 05:36:22] "GET /e/puy4/logout/ HTTP/1.1" 200 1243
Not Found: /e/puy4/home
[24/Apr/2019 05:36:22] "GET /e/puy4/home HTTP/1.1" 404 2718
[24/Apr/2019 05:36:27] "GET /e/puy4/ HTTP/1.1" 200 1343
Not Found: /e/puy4/home
[24/Apr/2019 05:36:37] "GET /e/puy4/home HTTP/1.1" 404 2718
[24/Apr/2019 05:36:38] "GET /e/puy4/logout/ HTTP/1.1" 200 1238
[24/Apr/2019 05:36:39] "GET /e/puy4/ HTTP/1.1" 200 1343
[24/Apr/2019 05:37:46] "GET /e/puy4/ HTTP/1.1" 200 1343
[24/Apr/2019 05:37:51] "GET /e/puy4/logout/ HTTP/1.1" 200 1251
[24/Apr/2019 05:37:53] "GET /e/puy4/ HTTP/1.1" 200 1343
[24/Apr/2019 05:37:54] "GET /e/puy4/logout/ HTTP/1.1" 200 1251
[24/Apr/2019 05:50:28] "GET /e/puy4/logout/ HTTP/1.1" 200 1151
[24/Apr/2019 05:50:48] "GET /e/puy4 HTTP/1.1" 301 0
[24/Apr/2019 05:50:48] "GET /e/puy4/ HTTP/1.1" 200 1165
[24/Apr/2019 05:52:00] "GET /e/puy4/ HTTP/1.1" 200 1344
[24/Apr/2019 05:52:02] "GET /e/puy4/login/ HTTP/1.1" 200 1593
[24/Apr/2019 05:52:13] "GET /e/puy4/ HTTP/1.1" 200 1347
[24/Apr/2019 05:52:30] "GET /e/puy4/ HTTP/1.1" 200 1360
[24/Apr/2019 06:12:50] "GET /e/puy4/ HTTP/1.1" 200 1360
Internal Server Error: /e/puy4/
Traceback (most recent call last):
  File "/home/puy4/CS1XA3/Project03/python_env/lib/python3.6/site-packages/django/template/base.py", line 470, in parse
    compile_func = self.tags[command]
KeyError: 'username'

During handling of the above exception, another exception occurred:

Traceback (most recent call last):
  File "/home/puy4/CS1XA3/Project03/python_env/lib/python3.6/site-packages/django/core/handlers/exception.py", line 34, in inner
    response = get_response(request)
  File "/home/puy4/CS1XA3/Project03/python_env/lib/python3.6/site-packages/django/core/handlers/base.py", line 115, in _get_response
    response = self.process_exception_by_middleware(e, request)
  File "/home/puy4/CS1XA3/Project03/python_env/lib/python3.6/site-packages/django/core/handlers/base.py", line 113, in _get_response
    response = wrapped_callback(request, *callback_args, **callback_kwargs)
  File "/home/puy4/CS1XA3/Project03/django_project/homepage1/views.py", line 9, in home
    return render(request, 'home.html', hometitle)
  File "/home/puy4/CS1XA3/Project03/python_env/lib/python3.6/site-packages/django/shortcuts.py", line 36, in render
    content = loader.render_to_string(template_name, context, request, using=using)
  File "/home/puy4/CS1XA3/Project03/python_env/lib/python3.6/site-packages/django/template/loader.py", line 61, in render_to_string
    template = get_template(template_name, using=using)
  File "/home/puy4/CS1XA3/Project03/python_env/lib/python3.6/site-packages/django/template/loader.py", line 15, in get_template
    return engine.get_template(template_name)
  File "/home/puy4/CS1XA3/Project03/python_env/lib/python3.6/site-packages/django/template/backends/django.py", line 34, in get_template
    return Template(self.engine.get_template(template_name), self)
  File "/home/puy4/CS1XA3/Project03/python_env/lib/python3.6/site-packages/django/template/engine.py", line 143, in get_template
    template, origin = self.find_template(template_name)
  File "/home/puy4/CS1XA3/Project03/python_env/lib/python3.6/site-packages/django/template/engine.py", line 125, in find_template
    template = loader.get_template(name, skip=skip)
  File "/home/puy4/CS1XA3/Project03/python_env/lib/python3.6/site-packages/django/template/loaders/base.py", line 30, in get_template
    contents, origin, origin.template_name, self.engine,
  File "/home/puy4/CS1XA3/Project03/python_env/lib/python3.6/site-packages/django/template/base.py", line 156, in __init__
    self.nodelist = self.compile_nodelist()
  File "/home/puy4/CS1XA3/Project03/python_env/lib/python3.6/site-packages/django/template/base.py", line 194, in compile_nodelist
    return parser.parse()
  File "/home/puy4/CS1XA3/Project03/python_env/lib/python3.6/site-packages/django/template/base.py", line 478, in parse
    raise self.error(token, e)
  File "/home/puy4/CS1XA3/Project03/python_env/lib/python3.6/site-packages/django/template/base.py", line 476, in parse
    compiled_result = compile_func(self, token)
  File "/home/puy4/CS1XA3/Project03/python_env/lib/python3.6/site-packages/django/template/loader_tags.py", line 266, in do_extends
    nodelist = parser.parse()
  File "/home/puy4/CS1XA3/Project03/python_env/lib/python3.6/site-packages/django/template/base.py", line 478, in parse
    raise self.error(token, e)
  File "/home/puy4/CS1XA3/Project03/python_env/lib/python3.6/site-packages/django/template/base.py", line 476, in parse
    compiled_result = compile_func(self, token)
  File "/home/puy4/CS1XA3/Project03/python_env/lib/python3.6/site-packages/django/template/loader_tags.py", line 209, in do_block
    nodelist = parser.parse(('endblock',))
  File "/home/puy4/CS1XA3/Project03/python_env/lib/python3.6/site-packages/django/template/base.py", line 472, in parse
    self.invalid_block_tag(token, command, parse_until)
  File "/home/puy4/CS1XA3/Project03/python_env/lib/python3.6/site-packages/django/template/base.py", line 528, in invalid_block_tag
    get_text_list(["'%s'" % p for p in parse_until], 'or'),
django.template.exceptions.TemplateSyntaxError: Invalid block tag on line 8: 'username', expected 'endblock'. Did you forget to register or load this tag?
[24/Apr/2019 06:56:22] "GET /e/puy4/ HTTP/1.1" 500 149120
[24/Apr/2019 06:58:52] "GET /e/puy4/ HTTP/1.1" 200 1375
[24/Apr/2019 06:58:55] "GET /e/puy4/login/ HTTP/1.1" 200 1609
[24/Apr/2019 06:58:56] "POST /e/puy4/login/ HTTP/1.1" 302 0
[24/Apr/2019 06:58:56] "GET /e/puy4/notes/ HTTP/1.1" 200 1569
[24/Apr/2019 06:59:30] "GET /e/puy4/notes/ HTTP/1.1" 200 1585
/home/puy4/CS1XA3/Project03/django_project/homepage1/views.py changed, reloading.
Performing system checks...

System check identified no issues (0 silenced).
April 24, 2019 - 05:24:14
Django version 2.2, using settings 'django_project.settings'
Starting development server at http://localhost:10048/
Quit the server with CONTROL-C.
Watching for file changes with StatReloader
[24/Apr/2019 07:04:52] "GET /e/puy4/notes/ HTTP/1.1" 200 1585
[24/Apr/2019 07:04:53] "GET /e/puy4/notes/ HTTP/1.1" 200 1585
[24/Apr/2019 07:04:53] "GET /e/puy4/notes/ HTTP/1.1" 200 1585
[24/Apr/2019 07:04:54] "GET /e/puy4/notes/ HTTP/1.1" 200 1585
[24/Apr/2019 07:04:54] "GET /e/puy4/notes/ HTTP/1.1" 200 1585
[24/Apr/2019 07:04:55] "GET /e/puy4/notes/ HTTP/1.1" 200 1585
[24/Apr/2019 07:04:55] "GET /e/puy4/notes/ HTTP/1.1" 200 1585
[24/Apr/2019 07:04:55] "GET /e/puy4/notes/ HTTP/1.1" 200 1585
[24/Apr/2019 07:04:56] "GET /e/puy4/notes/ HTTP/1.1" 200 1585
[24/Apr/2019 07:04:56] "GET /e/puy4/notes/ HTTP/1.1" 200 1585
[24/Apr/2019 07:04:56] "GET /e/puy4/notes/ HTTP/1.1" 200 1585
[24/Apr/2019 07:04:56] "GET /e/puy4/notes/ HTTP/1.1" 200 1585
[24/Apr/2019 07:04:57] "GET /e/puy4/notes/ HTTP/1.1" 200 1585
[24/Apr/2019 07:04:57] "GET /e/puy4/notes/ HTTP/1.1" 200 1585
[24/Apr/2019 07:04:59] "GET /e/puy4/notes/ HTTP/1.1" 200 1585
[24/Apr/2019 07:05:00] "GET /e/puy4/notes/ HTTP/1.1" 200 1585
[24/Apr/2019 07:05:01] "GET /e/puy4/ HTTP/1.1" 200 1360
[24/Apr/2019 07:05:02] "GET /e/puy4/login/ HTTP/1.1" 200 1609
[24/Apr/2019 07:05:03] "POST /e/puy4/login/ HTTP/1.1" 302 0
[24/Apr/2019 07:05:03] "GET /e/puy4/notes/ HTTP/1.1" 200 1585
[24/Apr/2019 07:05:32] "GET /e/puy4/notes/ HTTP/1.1" 200 1585
[24/Apr/2019 07:05:32] "GET /e/puy4/notes/ HTTP/1.1" 200 1585
[24/Apr/2019 07:06:14] "GET /e/puy4/notes/ HTTP/1.1" 200 1624
[24/Apr/2019 07:09:41] "GET /e/puy4/notes/ HTTP/1.1" 200 1596
[24/Apr/2019 07:09:42] "GET /e/puy4/notes/ HTTP/1.1" 200 1596
[24/Apr/2019 07:10:12] "GET /e/puy4/notes/ HTTP/1.1" 200 1588
[24/Apr/2019 16:35:35] "GET /e/puy4/notes/ HTTP/1.1" 200 1588
[24/Apr/2019 16:35:37] "GET /e/puy4/notes/ HTTP/1.1" 200 1588
[24/Apr/2019 16:35:38] "GET /e/puy4/ HTTP/1.1" 200 1360
[24/Apr/2019 16:36:44] "GET /e/puy4/login/ HTTP/1.1" 200 1609
[24/Apr/2019 17:46:05] "GET /e/puy4/notes/ HTTP/1.1" 200 1647
Forbidden (CSRF token missing or incorrect.): /e/puy4/notes/
[24/Apr/2019 17:46:07] "POST /e/puy4/notes/ HTTP/1.1" 403 2513
Forbidden (CSRF token missing or incorrect.): /e/puy4/notes/
[24/Apr/2019 17:47:05] "POST /e/puy4/notes/ HTTP/1.1" 403 2513
/home/puy4/CS1XA3/Project03/django_project/homepage1/views.py changed, reloading.
Performing system checks...

System check identified no issues (0 silenced).
April 24, 2019 - 07:04:27
Django version 2.2, using settings 'django_project.settings'
Starting development server at http://localhost:10048/
Quit the server with CONTROL-C.
Watching for file changes with StatReloader
Performing system checks...

Traceback (most recent call last):
  File "manage.py", line 21, in <module>
    main()
  File "manage.py", line 17, in main
    execute_from_command_line(sys.argv)
  File "/home/puy4/CS1XA3/Project03/python_env/lib/python3.6/site-packages/django/core/management/__init__.py", line 381, in execute_from_command_line
    utility.execute()
  File "/home/puy4/CS1XA3/Project03/python_env/lib/python3.6/site-packages/django/core/management/__init__.py", line 375, in execute
    self.fetch_command(subcommand).run_from_argv(self.argv)
  File "/home/puy4/CS1XA3/Project03/python_env/lib/python3.6/site-packages/django/core/management/base.py", line 323, in run_from_argv
    self.execute(*args, **cmd_options)
  File "/home/puy4/CS1XA3/Project03/python_env/lib/python3.6/site-packages/django/core/management/commands/runserver.py", line 60, in execute
    super().execute(*args, **options)
  File "/home/puy4/CS1XA3/Project03/python_env/lib/python3.6/site-packages/django/core/management/base.py", line 364, in execute
    output = self.handle(*args, **options)
  File "/home/puy4/CS1XA3/Project03/python_env/lib/python3.6/site-packages/django/core/management/commands/runserver.py", line 95, in handle
    self.run(**options)
  File "/home/puy4/CS1XA3/Project03/python_env/lib/python3.6/site-packages/django/core/management/commands/runserver.py", line 102, in run
    autoreload.run_with_reloader(self.inner_run, **options)
  File "/home/puy4/CS1XA3/Project03/python_env/lib/python3.6/site-packages/django/utils/autoreload.py", line 579, in run_with_reloader
    start_django(reloader, main_func, *args, **kwargs)
  File "/home/puy4/CS1XA3/Project03/python_env/lib/python3.6/site-packages/django/utils/autoreload.py", line 564, in start_django
    reloader.run(django_main_thread)
  File "/home/puy4/CS1XA3/Project03/python_env/lib/python3.6/site-packages/django/utils/autoreload.py", line 272, in run
    get_resolver().urlconf_module
  File "/home/puy4/CS1XA3/Project03/python_env/lib/python3.6/site-packages/django/utils/functional.py", line 80, in __get__
    res = instance.__dict__[self.name] = self.func(instance)
  File "/home/puy4/CS1XA3/Project03/python_env/lib/python3.6/site-packages/django/urls/resolvers.py", line 564, in urlconf_module
    return import_module(self.urlconf_name)
  File "/usr/lib/python3.6/importlib/__init__.py", line 126, in import_module
    return _bootstrap._gcd_import(name[level:], package, level)
  File "<frozen importlib._bootstrap>", line 994, in _gcd_import
  File "<frozen importlib._bootstrap>", line 971, in _find_and_load
  File "<frozen importlib._bootstrap>", line 955, in _find_and_load_unlocked
  File "<frozen importlib._bootstrap>", line 665, in _load_unlocked
  File "<frozen importlib._bootstrap_external>", line 678, in exec_module
  File "<frozen importlib._bootstrap>", line 219, in _call_with_frames_removed
  File "/home/puy4/CS1XA3/Project03/django_project/django_project/urls.py", line 25, in <module>
    path('e/puy4/', include('homepage1.urls')),
  File "/home/puy4/CS1XA3/Project03/python_env/lib/python3.6/site-packages/django/urls/conf.py", line 34, in include
    urlconf_module = import_module(urlconf_module)
  File "/usr/lib/python3.6/importlib/__init__.py", line 126, in import_module
    return _bootstrap._gcd_import(name[level:], package, level)
  File "<frozen importlib._bootstrap>", line 994, in _gcd_import
  File "<frozen importlib._bootstrap>", line 971, in _find_and_load
  File "<frozen importlib._bootstrap>", line 955, in _find_and_load_unlocked
  File "<frozen importlib._bootstrap>", line 665, in _load_unlocked
  File "<frozen importlib._bootstrap_external>", line 678, in exec_module
  File "<frozen importlib._bootstrap>", line 219, in _call_with_frames_removed
  File "/home/puy4/CS1XA3/Project03/django_project/homepage1/urls.py", line 2, in <module>
    from . import views
  File "/home/puy4/CS1XA3/Project03/django_project/homepage1/views.py", line 20
    input = 
           ^
SyntaxError: invalid syntax
Exception in thread Thread-1:
Traceback (most recent call last):
  File "/usr/lib/python3.6/threading.py", line 916, in _bootstrap_inner
    self.run()
  File "/usr/lib/python3.6/threading.py", line 864, in run
    self._target(*self._args, **self._kwargs)
  File "/home/puy4/CS1XA3/Project03/python_env/lib/python3.6/site-packages/django/utils/autoreload.py", line 54, in wrapper
    fn(*args, **kwargs)
  File "/home/puy4/CS1XA3/Project03/python_env/lib/python3.6/site-packages/django/core/management/commands/runserver.py", line 117, in inner_run
    self.check(display_num_errors=True)
  File "/home/puy4/CS1XA3/Project03/python_env/lib/python3.6/site-packages/django/core/management/base.py", line 390, in check
    include_deployment_checks=include_deployment_checks,
  File "/home/puy4/CS1XA3/Project03/python_env/lib/python3.6/site-packages/django/core/management/base.py", line 377, in _run_checks
    return checks.run_checks(**kwargs)
  File "/home/puy4/CS1XA3/Project03/python_env/lib/python3.6/site-packages/django/core/checks/registry.py", line 72, in run_checks
    new_errors = check(app_configs=app_configs)
  File "/home/puy4/CS1XA3/Project03/python_env/lib/python3.6/site-packages/django/core/checks/urls.py", line 13, in check_url_config
    return check_resolver(resolver)
  File "/home/puy4/CS1XA3/Project03/python_env/lib/python3.6/site-packages/django/core/checks/urls.py", line 23, in check_resolver
    return check_method()
  File "/home/puy4/CS1XA3/Project03/python_env/lib/python3.6/site-packages/django/urls/resolvers.py", line 398, in check
    for pattern in self.url_patterns:
  File "/home/puy4/CS1XA3/Project03/python_env/lib/python3.6/site-packages/django/utils/functional.py", line 80, in __get__
    res = instance.__dict__[self.name] = self.func(instance)
  File "/home/puy4/CS1XA3/Project03/python_env/lib/python3.6/site-packages/django/urls/resolvers.py", line 571, in url_patterns
    patterns = getattr(self.urlconf_module, "urlpatterns", self.urlconf_module)
  File "/home/puy4/CS1XA3/Project03/python_env/lib/python3.6/site-packages/django/utils/functional.py", line 80, in __get__
    res = instance.__dict__[self.name] = self.func(instance)
  File "/home/puy4/CS1XA3/Project03/python_env/lib/python3.6/site-packages/django/urls/resolvers.py", line 564, in urlconf_module
    return import_module(self.urlconf_name)
  File "/usr/lib/python3.6/importlib/__init__.py", line 126, in import_module
    return _bootstrap._gcd_import(name[level:], package, level)
  File "<frozen importlib._bootstrap>", line 994, in _gcd_import
  File "<frozen importlib._bootstrap>", line 971, in _find_and_load
  File "<frozen importlib._bootstrap>", line 955, in _find_and_load_unlocked
  File "<frozen importlib._bootstrap>", line 665, in _load_unlocked
  File "<frozen importlib._bootstrap_external>", line 678, in exec_module
  File "<frozen importlib._bootstrap>", line 219, in _call_with_frames_removed
  File "/home/puy4/CS1XA3/Project03/django_project/django_project/urls.py", line 25, in <module>
    path('e/puy4/', include('homepage1.urls')),
  File "/home/puy4/CS1XA3/Project03/python_env/lib/python3.6/site-packages/django/urls/conf.py", line 34, in include
    urlconf_module = import_module(urlconf_module)
  File "/usr/lib/python3.6/importlib/__init__.py", line 126, in import_module
    return _bootstrap._gcd_import(name[level:], package, level)
  File "<frozen importlib._bootstrap>", line 994, in _gcd_import
  File "<frozen importlib._bootstrap>", line 971, in _find_and_load
  File "<frozen importlib._bootstrap>", line 955, in _find_and_load_unlocked
  File "<frozen importlib._bootstrap>", line 665, in _load_unlocked
  File "<frozen importlib._bootstrap_external>", line 678, in exec_module
  File "<frozen importlib._bootstrap>", line 219, in _call_with_frames_removed
  File "/home/puy4/CS1XA3/Project03/django_project/homepage1/urls.py", line 2, in <module>
    from . import views
  File "/home/puy4/CS1XA3/Project03/django_project/homepage1/views.py", line 20
    input =
           ^
SyntaxError: invalid syntax

Watching for file changes with StatReloader
[24/Apr/2019 18:24:27] "GET /e/puy4/ HTTP/1.1" 200 1360
[24/Apr/2019 18:24:32] "GET /e/puy4/login/ HTTP/1.1" 200 1609
[24/Apr/2019 18:24:33] "POST /e/puy4/login/ HTTP/1.1" 302 0
[24/Apr/2019 18:24:33] "GET /e/puy4/notes/ HTTP/1.1" 200 1663
/home/puy4/CS1XA3/Project03/django_project/homepage1/views.py changed, reloading.
Performing system checks...

System check identified no issues (0 silenced).
April 24, 2019 - 18:24:23
Django version 2.2, using settings 'django_project.settings'
Starting development server at http://localhost:10048/
Quit the server with CONTROL-C.
Watching for file changes with StatReloader
Performing system checks...

Traceback (most recent call last):
  File "manage.py", line 21, in <module>
    main()
  File "manage.py", line 17, in main
    execute_from_command_line(sys.argv)
  File "/home/puy4/.local/lib/python3.6/site-packages/django/core/management/__init__.py", line 381, in execute_from_command_line
    utility.execute()
  File "/home/puy4/.local/lib/python3.6/site-packages/django/core/management/__init__.py", line 375, in execute
    self.fetch_command(subcommand).run_from_argv(self.argv)
  File "/home/puy4/.local/lib/python3.6/site-packages/django/core/management/base.py", line 323, in run_from_argv
    self.execute(*args, **cmd_options)
  File "/home/puy4/.local/lib/python3.6/site-packages/django/core/management/commands/runserver.py", line 60, in execute
    super().execute(*args, **options)
  File "/home/puy4/.local/lib/python3.6/site-packages/django/core/management/base.py", line 364, in execute
    output = self.handle(*args, **options)
  File "/home/puy4/.local/lib/python3.6/site-packages/django/core/management/commands/runserver.py", line 95, in handle
    self.run(**options)
  File "/home/puy4/.local/lib/python3.6/site-packages/django/core/management/commands/runserver.py", line 102, in run
    autoreload.run_with_reloader(self.inner_run, **options)
  File "/home/puy4/.local/lib/python3.6/site-packages/django/utils/autoreload.py", line 579, in run_with_reloader
    start_django(reloader, main_func, *args, **kwargs)
  File "/home/puy4/.local/lib/python3.6/site-packages/django/utils/autoreload.py", line 564, in start_django
    reloader.run(django_main_thread)
  File "/home/puy4/.local/lib/python3.6/site-packages/django/utils/autoreload.py", line 272, in run
    get_resolver().urlconf_module
  File "/home/puy4/.local/lib/python3.6/site-packages/django/utils/functional.py", line 80, in __get__
    res = instance.__dict__[self.name] = self.func(instance)
  File "/home/puy4/.local/lib/python3.6/site-packages/django/urls/resolvers.py", line 564, in urlconf_module
    return import_module(self.urlconf_name)
  File "/usr/lib/python3.6/importlib/__init__.py", line 126, in import_module
    return _bootstrap._gcd_import(name[level:], package, level)
  File "<frozen importlib._bootstrap>", line 994, in _gcd_import
  File "<frozen importlib._bootstrap>", line 971, in _find_and_load
  File "<frozen importlib._bootstrap>", line 955, in _find_and_load_unlocked
  File "<frozen importlib._bootstrap>", line 665, in _load_unlocked
  File "<frozen importlib._bootstrap_external>", line 678, in exec_module
  File "<frozen importlib._bootstrap>", line 219, in _call_with_frames_removed
  File "/home/puy4/CS1XA3/Project03/django_project/django_project/urls.py", line 25, in <module>
    path('e/puy4/', include('homepage1.urls')),
  File "/home/puy4/.local/lib/python3.6/site-packages/django/urls/conf.py", line 34, in include
    urlconf_module = import_module(urlconf_module)
  File "/usr/lib/python3.6/importlib/__init__.py", line 126, in import_module
Exception in thread Thread-1:
Traceback (most recent call last):
  File "/usr/lib/python3.6/threading.py", line 916, in _bootstrap_inner
    self.run()
  File "/usr/lib/python3.6/threading.py", line 864, in run
    self._target(*self._args, **self._kwargs)
  File "/home/puy4/.local/lib/python3.6/site-packages/django/utils/autoreload.py", line 54, in wrapper
    fn(*args, **kwargs)
  File "/home/puy4/.local/lib/python3.6/site-packages/django/core/management/commands/runserver.py", line 117, in inner_run
    self.check(display_num_errors=True)
  File "/home/puy4/.local/lib/python3.6/site-packages/django/core/management/base.py", line 390, in check
    include_deployment_checks=include_deployment_checks,
  File "/home/puy4/.local/lib/python3.6/site-packages/django/core/management/base.py", line 377, in _run_checks
    return checks.run_checks(**kwargs)
  File "/home/puy4/.local/lib/python3.6/site-packages/django/core/checks/registry.py", line 72, in run_checks
    new_errors = check(app_configs=app_configs)
  File "/home/puy4/.local/lib/python3.6/site-packages/django/core/checks/urls.py", line 40, in check_url_namespaces_unique
    all_namespaces = _load_all_namespaces(resolver)
  File "/home/puy4/.local/lib/python3.6/site-packages/django/core/checks/urls.py", line 57, in _load_all_namespaces
    url_patterns = getattr(resolver, 'url_patterns', [])
  File "/home/puy4/.local/lib/python3.6/site-packages/django/utils/functional.py", line 80, in __get__
    res = instance.__dict__[self.name] = self.func(instance)
  File "/home/puy4/.local/lib/python3.6/site-packages/django/urls/resolvers.py", line 571, in url_patterns
    patterns = getattr(self.urlconf_module, "urlpatterns", self.urlconf_module)
  File "/home/puy4/.local/lib/python3.6/site-packages/django/utils/functional.py", line 80, in __get__
    res = instance.__dict__[self.name] = self.func(instance)
  File "/home/puy4/.local/lib/python3.6/site-packages/django/urls/resolvers.py", line 564, in urlconf_module
    return import_module(self.urlconf_name)
  File "/usr/lib/python3.6/importlib/__init__.py", line 126, in import_module
    return _bootstrap._gcd_import(name[level:], package, level)
  File "<frozen importlib._bootstrap>", line 994, in _gcd_import
  File "<frozen importlib._bootstrap>", line 971, in _find_and_load
  File "<frozen importlib._bootstrap>", line 955, in _find_and_load_unlocked
  File "<frozen importlib._bootstrap>", line 665, in _load_unlocked
  File "<frozen importlib._bootstrap_external>", line 678, in exec_module
  File "<frozen importlib._bootstrap>", line 219, in _call_with_frames_removed
  File "/home/puy4/CS1XA3/Project03/django_project/django_project/urls.py", line 25, in <module>
    path('e/puy4/', include('homepage1.urls')),
  File "/home/puy4/.local/lib/python3.6/site-packages/django/urls/conf.py", line 34, in include
    urlconf_module = import_module(urlconf_module)
  File "/usr/lib/python3.6/importlib/__init__.py", line 126, in import_module
    return _bootstrap._gcd_import(name[level:], package, level)
  File "<frozen importlib._bootstrap>", line 994, in _gcd_import
  File "<frozen importlib._bootstrap>", line 971, in _find_and_load
  File "<frozen importlib._bootstrap>", line 955, in _find_and_load_unlocked
  File "<frozen importlib._bootstrap>", line 665, in _load_unlocked
  File "<frozen importlib._bootstrap_external>", line 678, in exec_module
  File "<frozen importlib._bootstrap>", line 219, in _call_with_frames_removed
  File "/home/puy4/CS1XA3/Project03/django_project/homepage1/urls.py", line 2, in <module>
    from . import views
  File "/home/puy4/CS1XA3/Project03/django_project/homepage1/views.py", line 18
    form = PostForm(request.POST or none, request)
                                                 ^
IndentationError: unindent does not match any outer indentation level

    return _bootstrap._gcd_import(name[level:], package, level)
  File "<frozen importlib._bootstrap>", line 994, in _gcd_import
  File "<frozen importlib._bootstrap>", line 971, in _find_and_load
  File "<frozen importlib._bootstrap>", line 955, in _find_and_load_unlocked
  File "<frozen importlib._bootstrap>", line 665, in _load_unlocked
  File "<frozen importlib._bootstrap_external>", line 678, in exec_module
  File "<frozen importlib._bootstrap>", line 219, in _call_with_frames_removed
  File "/home/puy4/CS1XA3/Project03/django_project/homepage1/urls.py", line 2, in <module>
    from . import views
  File "/home/puy4/CS1XA3/Project03/django_project/homepage1/views.py", line 18
    form = PostForm(request.POST or none, request)
                                                 ^
IndentationError: unindent does not match any outer indentation level
Watching for file changes with StatReloader
[24/Apr/2019 19:39:43] "GET /e/puy4/ HTTP/1.1" 200 1360
[24/Apr/2019 19:39:44] "GET /e/puy4/login/ HTTP/1.1" 200 1609
[24/Apr/2019 19:39:45] "POST /e/puy4/login/ HTTP/1.1" 302 0
Internal Server Error: /e/puy4/notes/
Traceback (most recent call last):
  File "/home/puy4/.local/lib/python3.6/site-packages/django/core/handlers/exception.py", line 34, in inner
    response = get_response(request)
  File "/home/puy4/.local/lib/python3.6/site-packages/django/core/handlers/base.py", line 115, in _get_response
    response = self.process_exception_by_middleware(e, request)
  File "/home/puy4/.local/lib/python3.6/site-packages/django/core/handlers/base.py", line 113, in _get_response
    response = wrapped_callback(request, *callback_args, **callback_kwargs)
  File "/home/puy4/CS1XA3/Project03/django_project/homepage1/views.py", line 13, in notes
    return render(request, 'notes.html', notes)
  File "/home/puy4/.local/lib/python3.6/site-packages/django/shortcuts.py", line 36, in render
    content = loader.render_to_string(template_name, context, request, using=using)
  File "/home/puy4/.local/lib/python3.6/site-packages/django/template/loader.py", line 62, in render_to_string
    return template.render(context, request)
  File "/home/puy4/.local/lib/python3.6/site-packages/django/template/backends/django.py", line 59, in render
    context = make_context(context, request, autoescape=self.backend.engine.autoescape)
  File "/home/puy4/.local/lib/python3.6/site-packages/django/template/context.py", line 270, in make_context
    raise TypeError('context must be a dict rather than %s.' % context.__class__.__name__)
TypeError: context must be a dict rather than QuerySet.
[24/Apr/2019 19:39:45] "GET /e/puy4/notes/ HTTP/1.1" 500 80008
/home/puy4/CS1XA3/Project03/django_project/homepage1/views.py changed, reloading.
Performing system checks...

System check identified no issues (0 silenced).
April 24, 2019 - 19:39:38
Django version 2.2, using settings 'django_project.settings'
Starting development server at http://localhost:10048/
Quit the server with CONTROL-C.
Watching for file changes with StatReloader
[24/Apr/2019 19:42:49] "GET /e/puy4/ HTTP/1.1" 200 1360
[24/Apr/2019 19:42:50] "GET /e/puy4/login/ HTTP/1.1" 200 1609
[24/Apr/2019 19:42:51] "POST /e/puy4/login/ HTTP/1.1" 302 0
Internal Server Error: /e/puy4/notes/
Traceback (most recent call last):
  File "/home/puy4/.local/lib/python3.6/site-packages/django/core/handlers/exception.py", line 34, in inner
    response = get_response(request)
  File "/home/puy4/.local/lib/python3.6/site-packages/django/core/handlers/base.py", line 115, in _get_response
    response = self.process_exception_by_middleware(e, request)
  File "/home/puy4/.local/lib/python3.6/site-packages/django/core/handlers/base.py", line 113, in _get_response
    response = wrapped_callback(request, *callback_args, **callback_kwargs)
  File "/home/puy4/CS1XA3/Project03/django_project/homepage1/views.py", line 12, in notes
    notes = Post.objects.all().filter(request.user)
  File "/home/puy4/.local/lib/python3.6/site-packages/django/db/models/query.py", line 892, in filter
    return self._filter_or_exclude(False, *args, **kwargs)
  File "/home/puy4/.local/lib/python3.6/site-packages/django/db/models/query.py", line 910, in _filter_or_exclude
    clone.query.add_q(Q(*args, **kwargs))
  File "/home/puy4/.local/lib/python3.6/site-packages/django/db/models/sql/query.py", line 1290, in add_q
    clause, _ = self._add_q(q_object, self.used_aliases)
  File "/home/puy4/.local/lib/python3.6/site-packages/django/db/models/sql/query.py", line 1318, in _add_q
    split_subq=split_subq, simple_col=simple_col,
  File "/home/puy4/.local/lib/python3.6/site-packages/django/db/models/sql/query.py", line 1187, in build_filter
    arg, value = filter_expr
  File "/home/puy4/.local/lib/python3.6/site-packages/django/utils/functional.py", line 257, in inner
    return func(self._wrapped, *args)
TypeError: 'User' object is not iterable
[24/Apr/2019 19:42:51] "GET /e/puy4/notes/ HTTP/1.1" 500 90700
/home/puy4/CS1XA3/Project03/django_project/homepage1/views.py changed, reloading.
Performing system checks...

System check identified no issues (0 silenced).
April 24, 2019 - 19:42:35
Django version 2.2, using settings 'django_project.settings'
Starting development server at http://localhost:10048/
Quit the server with CONTROL-C.
Watching for file changes with StatReloader
Internal Server Error: /e/puy4/notes/
Traceback (most recent call last):
  File "/home/puy4/.local/lib/python3.6/site-packages/django/core/handlers/exception.py", line 34, in inner
    response = get_response(request)
  File "/home/puy4/.local/lib/python3.6/site-packages/django/core/handlers/base.py", line 115, in _get_response
    response = self.process_exception_by_middleware(e, request)
  File "/home/puy4/.local/lib/python3.6/site-packages/django/core/handlers/base.py", line 113, in _get_response
    response = wrapped_callback(request, *callback_args, **callback_kwargs)
  File "/home/puy4/CS1XA3/Project03/django_project/homepage1/views.py", line 12, in notes
    notes = Post.objects.all().filter(request.user)
  File "/home/puy4/.local/lib/python3.6/site-packages/django/db/models/query.py", line 892, in filter
    return self._filter_or_exclude(False, *args, **kwargs)
  File "/home/puy4/.local/lib/python3.6/site-packages/django/db/models/query.py", line 910, in _filter_or_exclude
    clone.query.add_q(Q(*args, **kwargs))
  File "/home/puy4/.local/lib/python3.6/site-packages/django/db/models/sql/query.py", line 1290, in add_q
    clause, _ = self._add_q(q_object, self.used_aliases)
  File "/home/puy4/.local/lib/python3.6/site-packages/django/db/models/sql/query.py", line 1318, in _add_q
    split_subq=split_subq, simple_col=simple_col,
  File "/home/puy4/.local/lib/python3.6/site-packages/django/db/models/sql/query.py", line 1187, in build_filter
    arg, value = filter_expr
  File "/home/puy4/.local/lib/python3.6/site-packages/django/utils/functional.py", line 257, in inner
    return func(self._wrapped, *args)
TypeError: 'User' object is not iterable
[24/Apr/2019 21:03:02] "GET /e/puy4/notes/ HTTP/1.1" 500 90700
Internal Server Error: /e/puy4/notes/
Traceback (most recent call last):
  File "/home/puy4/.local/lib/python3.6/site-packages/django/core/handlers/exception.py", line 34, in inner
    response = get_response(request)
  File "/home/puy4/.local/lib/python3.6/site-packages/django/core/handlers/base.py", line 115, in _get_response
    response = self.process_exception_by_middleware(e, request)
  File "/home/puy4/.local/lib/python3.6/site-packages/django/core/handlers/base.py", line 113, in _get_response
    response = wrapped_callback(request, *callback_args, **callback_kwargs)
  File "/home/puy4/CS1XA3/Project03/django_project/homepage1/views.py", line 12, in notes
    notes = Post.objects.all().filter(request.user)
  File "/home/puy4/.local/lib/python3.6/site-packages/django/db/models/query.py", line 892, in filter
    return self._filter_or_exclude(False, *args, **kwargs)
  File "/home/puy4/.local/lib/python3.6/site-packages/django/db/models/query.py", line 910, in _filter_or_exclude
    clone.query.add_q(Q(*args, **kwargs))
  File "/home/puy4/.local/lib/python3.6/site-packages/django/db/models/sql/query.py", line 1290, in add_q
    clause, _ = self._add_q(q_object, self.used_aliases)
  File "/home/puy4/.local/lib/python3.6/site-packages/django/db/models/sql/query.py", line 1318, in _add_q
    split_subq=split_subq, simple_col=simple_col,
  File "/home/puy4/.local/lib/python3.6/site-packages/django/db/models/sql/query.py", line 1187, in build_filter
    arg, value = filter_expr
  File "/home/puy4/.local/lib/python3.6/site-packages/django/utils/functional.py", line 257, in inner
    return func(self._wrapped, *args)
TypeError: 'User' object is not iterable
[24/Apr/2019 21:03:04] "GET /e/puy4/notes/ HTTP/1.1" 500 90541
[24/Apr/2019 21:03:05] "GET /e/puy4/ HTTP/1.1" 200 1360
/home/puy4/CS1XA3/Project03/django_project/homepage1/views.py changed, reloading.
Performing system checks...

System check identified no issues (0 silenced).
April 24, 2019 - 20:16:57
Django version 2.2, using settings 'django_project.settings'
Starting development server at http://localhost:10048/
Quit the server with CONTROL-C.
Watching for file changes with StatReloader
[24/Apr/2019 21:05:20] "GET /e/puy4/login/ HTTP/1.1" 200 1609
[24/Apr/2019 21:05:21] "POST /e/puy4/login/ HTTP/1.1" 302 0
Internal Server Error: /e/puy4/notes/
Traceback (most recent call last):
  File "/home/puy4/.local/lib/python3.6/site-packages/django/core/handlers/exception.py", line 34, in inner
    response = get_response(request)
  File "/home/puy4/.local/lib/python3.6/site-packages/django/core/handlers/base.py", line 115, in _get_response
    response = self.process_exception_by_middleware(e, request)
  File "/home/puy4/.local/lib/python3.6/site-packages/django/core/handlers/base.py", line 113, in _get_response
    response = wrapped_callback(request, *callback_args, **callback_kwargs)
  File "/home/puy4/CS1XA3/Project03/django_project/homepage1/views.py", line 12, in notes
    notes = Post.objects.all().filter(request.user)
  File "/home/puy4/.local/lib/python3.6/site-packages/django/db/models/query.py", line 892, in filter
    return self._filter_or_exclude(False, *args, **kwargs)
  File "/home/puy4/.local/lib/python3.6/site-packages/django/db/models/query.py", line 910, in _filter_or_exclude
    clone.query.add_q(Q(*args, **kwargs))
  File "/home/puy4/.local/lib/python3.6/site-packages/django/db/models/sql/query.py", line 1290, in add_q
    clause, _ = self._add_q(q_object, self.used_aliases)
  File "/home/puy4/.local/lib/python3.6/site-packages/django/db/models/sql/query.py", line 1318, in _add_q
    split_subq=split_subq, simple_col=simple_col,
  File "/home/puy4/.local/lib/python3.6/site-packages/django/db/models/sql/query.py", line 1187, in build_filter
    arg, value = filter_expr
  File "/home/puy4/.local/lib/python3.6/site-packages/django/utils/functional.py", line 257, in inner
    return func(self._wrapped, *args)
TypeError: 'User' object is not iterable
[24/Apr/2019 21:05:22] "GET /e/puy4/notes/ HTTP/1.1" 500 90718
/home/puy4/CS1XA3/Project03/django_project/homepage1/views.py changed, reloading.
Performing system checks...

System check identified no issues (0 silenced).
April 24, 2019 - 21:05:18
Django version 2.2, using settings 'django_project.settings'
Starting development server at http://localhost:10048/
Quit the server with CONTROL-C.
Watching for file changes with StatReloader
[24/Apr/2019 21:05:44] "GET /e/puy4/notes/ HTTP/1.1" 200 1584
Forbidden (CSRF token missing or incorrect.): /e/puy4/notes/
[24/Apr/2019 21:05:47] "POST /e/puy4/notes/ HTTP/1.1" 403 2513
/home/puy4/CS1XA3/Project03/django_project/homepage1/views.py changed, reloading.
Performing system checks...

System check identified no issues (0 silenced).
April 24, 2019 - 21:05:41
Django version 2.2, using settings 'django_project.settings'
Starting development server at http://localhost:10048/
Quit the server with CONTROL-C.
Watching for file changes with StatReloader
